Workbook

Sheet GENERAL
A1: n | B1: Mes | C1: Fecha | D1: Canal | E1: Local | F1: Área | G1: Optómetra | H1: Asesor | I1: Momento | J1: Calificación | K1: Pregunta | L1: Responde | M1: Comentario | N1: CLIENTE | O1: ID | P1: CONTACTO | Q1: Correos disculpa | R1: llamada cliente | S1: Contestó | T1: OBSERVACIÓN / GESTIÓN DE LLAMADAS | U1: SOLUCIÓN | V1: quien llama | W1: CLASIFICACION
A2: 1 | B2: Enero | C2: 46024 | D2: Telegram | E2: SAN MARINO | F2: Ventas | G2: TAPIA PEÑA JESSIE PAMELA | H2: RIVADENEIRA PARRA JONATHAN SEBASTIAN | I2: M1 | J2: 5 | K2: El asesoramiento recibido por el asesor fue: | L2: NO | M2: Informacion entregada incompleta | R2: no
A3: 2 | B3: Enero | C3: 46024 | D3: Telegram | E3: SAN MARINO | F3: Ventas | G3: TAPIA PEÑA JESSIE PAMELA | H3: RIVADENEIRA PARRA JONATHAN SEBASTIAN | I3: M1 | J3: 1 | K3: ¿Qué tan satisfecho está con la explicación que le dio el asesor respecto a la garantía extendida? | L3: NO | M3: No se otorgo ninguna explicacion mas alla de en que aplica, mas no como aplicarla | R3: no
A4: 3 | B4: Enero | C4: 46024 | D4: Telegram | E4: SAN MARINO | F4: Optometría | G4: TAPIA PEÑA JESSIE PAMELA | H4: RIVADENEIRA PARRA JONATHAN SEBASTIAN | I4: M3 | J4: 1 | K4: ¿Recomendaría Óptica Los Andes a un familiar o amigo? | L4: NO | M4: Me entregaron los lentes con las lunas cambiadas entre sí, y tuve que regresar al día siguiente porque fui donde mi oftalmólogo y me dijo que eran incorrectas las medidas!, cuando regresé a su local del San Marino, la técnica encargada revisó y verificó los lentes y ella se dió cuenta que las lunas estaban cambiadas entre sí!!!...y tuvo el descaro de decirme que ella las había verificado antes de entregarme las!!...o sea que yo las había cambiado!!....cuando no era de ninguna forma eso posible!!!...me enojé mucho por discutirme e insistir en que ella las había entregado perfectas!!... pésima atención!!...a la final las recibí de vuelta pero me quedó la desconfianza por el mal rato que pasé y al haberme dado cuenta que tuvieron falla en su trabajo profesional!!!...no quiero ni usar esos lentes que me costaron más de $400 y a la final me sentí engañada porque la señorita que me atendió en la venta me dijo que era el mejor lente progresivo!!..y resulta que había otro mucho mejor!!... porque los campos visuales laterales me molestan!.... pésima experiencia está vez porque ya les he comprado antes y sin inconvenientes!. | N4: ALEJANDRO SANCHEZ | O4: 0903972685001 | P4: 0983676992 | Q4: si | T4: Cliente no contestó
A5: 4 | B5: Enero | C5: 46025 | D5: Telegram | E5: SCALA SHOPING OSH | F5: Ventas | G5: ALDANA GOMEZ ANDREA | H5: SANCHEZ CHECA BRYAN ADRIAN | I5: M1 | J5: 1 | K5: ¿Recomendaría Óptica Los Andes a un familiar o amigo? | L5: NO | M5: El día de ayer 2 de enero realicé una compra en el local de Sunglass Hut de El Escala de unas gafas Ray-Ban que habíamos solicitado como regalo. Al llegar a casa nos dimos cuenta de que el modelo entregado no era el correcto. Regresamos hoy para solicitar la devolución, ya que el modelo correcto no está disponible, pero nos indicaron que no devuelven el dinero y que no pueden conseguir el modelo correcto Soy cliente de la marca desde hace muchos años y considero que esta respuesta no es adecuada, ya que el error no fue nuestro. Solicito una solución favorable, idealmente la devolución del valor pagado. Quedo atento a su respuesta. Gustavo Schneider 0999190138 | N5: GUSTAVO SCHNEIDER | O5: 1708531213 | P5: 0999190138 | Q5: si | R5: no | T5: si se hizo el cambio para nota de crédito, se habló con el local y el cliente llamó al 1800, le dieron una caja de gafa Rayban
A6: 5 | B6: Enero | C6: 46025 | D6: Telegram | E6: MALL EL JARDIN OSH | F6: Ventas | G6: BAÑO LUCERO DAYANA LISBETH | H6: VERDEZOTO VELEZ JONATHAN ALEXANDER | I6: M1 | J6: 5 | K6: El asesoramiento recibido por el asesor fue: | L6: NO | M6: Poca asesoria | R6: no
A7: 6 | B7: Enero | C7: 46025 | D7: Telegram | E7: MALL EL JARDIN OSH | F7: Ventas | G7: BAÑO LUCERO DAYANA LISBETH | H7: VERDEZOTO VELEZ JONATHAN ALEXANDER | I7: M1 | J7: 4 | K7: Las recomendaciones recibidas por el optómetra fue: | L7: NO | M7: Pocas recomendaciones | R7: no
A8: 7 | B8: Enero | C8: 46026 | D8: Telegram | E8: QUICENTRO SUR | F8: Ventas | G8: ECHEVERRIA NOBOA HIPATIA MAGDALENA | H8: BARRERA GORDON HERMEN GUSTAVO | I8: M2 | J8: NO | K8: ¿El tiempo de entrega de su producto fue acorde al tiempo ofrecido? | L8: NO | M8: Se demoraron casi dos semanas | R8: no
A9: 8 | B9: Enero | C9: 46026 | D9: Telegram | E9: POLICENTRO | F9: Ventas | G9: CASTRO IBARRA CINDY JAZMIN | H9: GUERRA PINCAY LIDIA LISBETH | I9: M3 | J9: 1 | K9: ¿Recomendaría Óptica Los Andes a un familiar o amigo? | L9: NO | M9: Las optometrías y la de atención al cliente no me entregaron el estuche de la marca de los armazones q compré. Terrible servicio. | N9: OSWALDO ANDRES MORENO PEREZ | O9: 1308634896 | P9: 0996767379 | Q9: si | R9: no | T9: es gafa
A10: 9 | B10: Enero | C10: 46026 | D10: Telegram | E10: QUICENTRO SUR | F10: Ventas | G10: ECHEVERRIA NOBOA HIPATIA MAGDALENA | H10: ALAVA SOLORZANO JEFFERSON CRISTHIAN | I10: M2 | J10: NO | K10: ¿El tiempo de entrega de su producto fue acorde al tiempo ofrecido? | L10: NO | M10: De 5-6 días y me entregaron a los 10 días | R10: no
A11: 10 | B11: Enero | C11: 46027 | D11: Telegram | E11: SAN LUIS | F11: Ventas | G11: MOJICA GARCIA ALFONSO JAVIER | H11: DAVILA OSSA MARCELO EDUARDO | I11: M3 | J11: NO | K11: ¿Recomendaría Óptica Los Andes a un familiar o amigo? | L11: NO | M11: No me llamaron para entregar mis lentes | N11: KLEVER FRANCISCO FRANCISCO ENRIQUEZ CHANGO CHANGO | O11: 1716567936 | P11: 0979538182 | Q11: si | R11: no | T11: Tus lentes ya estan listos en el local SAN LUIS tel 0998661846 / mensaje si se envío
A12: 11 | B12: Enero | C12: 46027 | D12: Telegram | E12: MALL EL JARDIN | F12: Ventas | G12: CUASCOTA MALTE ROBERTO CARLOS | H12: RUIZ CARREÑO FREDDY SANTIAGO | I12: M2 | J12: 6 | K12: ¿Recomendaría Óptica Los Andes a un familiar o amigo? | L12: NO | M12: Estoy muy insatisfecho con los Marcos que compré, no llevan ni un mes y me quedan completamente flojos y se descuadran | N12: ALBAN SANTAMARIA JORGE ESTALIO | O12: 1719626820 | P12: 0995414001 | Q12: si | R12: si | T12: va mas de 10 años comprando con nosotros y esta vez tiene problemas, los marcos están descuadrados, se marea cuando los usa, me mareo, se resbalan, compra lo mejor, no ha podido ir al local para revisión, va a ir al San Luis
A13: 12 | B13: Enero | C13: 46027 | D13: Telegram | E13: MALL EL JARDIN | F13: Ventas | G13: CUASCOTA MALTE ROBERTO CARLOS | H13: RUIZ CARREÑO FREDDY SANTIAGO | I13: M2 | J13: 5 | K13: La atención del asesor con respecto a la explicación del cuidado y la garantía del producto fue: | L13: NO | M13: No me dio ninguna asesoría sobre el tema de garantía | R13: no
A14: 13 | B14: Enero | C14: 46028 | D14: Telegram | E14: RIOCENTRO CEIBOS | F14: Ventas | G14: MORANTE LEON MARIA | H14: GOMEZ LEON NAYDELYN ESCARLETH | I14: M2 | J14: NO | K14: ¿Le entregaron la factura física el momento de su compra? | L14: NO | M14: NO | R14: no
A15: 14 | B15: Enero | C15: 46028 | D15: Telegram | E15: QUICENTRO SHOPPING | F15: Ventas | G15: NUÑEZ MONAR SILVANA GISSELA | H15: YEPEZ PAVON DAVID GUSTAVO | I15: M1 | J15: 5 | K15: El asesoramiento recibido por el asesor fue: | L15: NO | M15: Al ser un accesorio estético el acompañamiento del asesor debe ser más empático y cercano con el cliente en el sentido de dar las mejores recomendaciones, más allá de "¿qué es lo que le gusta?" | R15: no
A16: 15 | B16: Enero | C16: 46028 | D16: Telegram | E16: QUICENTRO SHOPPING | F16: Ventas | G16: NUÑEZ MONAR SILVANA GISSELA | H16: YEPEZ PAVON DAVID GUSTAVO | I16: M1 | J16: 5 | K16: Las recomendaciones recibidas por el optómetra fue: | L16: NO | M16: Mas o menos | R16: no
A17: 16 | B17: Enero | C17: 46028 | D17: Telegram | E17: BOSQUE 1 | F17: Ventas | G17: GUERRERO AIZAGA KATHERINE LIZBETH | H17: GUATEMAL OTAVALO MARIA GABRIELA | I17: M2 | J17: 5 | K17: ¿Recomendaría Óptica Los Andes a un familiar o amigo? | L17: NO | M17: elevado el precio | N17: MARIA FERNANDA VARGAS | O17: 1711689354 | P17: 0996503390 | Q17: si | R17: no | T17: respondió al correo de disculpas, por confirmar devolución
A18: 17 | B18: Enero | C18: 46028 | D18: Telegram | E18: VILLAGE PLAZA | F18: Ventas | G18: SAMAN JIMENEZ PAOLO CESAR | H18: OCHOA TORRES CESAR ENRIQUE | I18: M1 | J18: 2 | K18: ¿Recomendaría Óptica Los Andes a un familiar o amigo? | L18: NO | M18: Mal atendida por el vendedor | N18: MAIRA ROSA MENDOZA SARABIA MAIRA ROSA MENDOZA SARABIA SARABIA | O18: 1204269953001 | P18: 0959598124 | Q18: si | R18: no
A19: 18 | B19: Enero | C19: 46028 | D19: Telegram | E19: VILLAGE PLAZA | F19: Ventas | G19: SAMAN JIMENEZ PAOLO CESAR | H19: OCHOA TORRES CESAR ENRIQUE | I19: M1 | J19: 1 | K19: El asesoramiento recibido por el asesor fue: | L19: NO | M19: No me gusto | R19: no
A20: 19 | B20: Enero | C20: 46028 | D20: Telegram | E20: CCI 1 | F20: Ventas | G20: NARVAEZ OBANDO LIDIA VERONICA | H20: JACOME NOBOA PATRICIO JAVIER | I20: M1 | J20: 5 | K20: ¿Qué tan satisfecho está con la explicación que le dio el asesor respecto a la garantía extendida? | L20: NO | M20: Falto información | R20: no
A21: 20 | B21: Enero | C21: 46028 | D21: Telegram | E21: MALL DEL NORTE | F21: Ventas | G21: POZO RONQUILLO SEBASTIAN GABRIEL | H21: ZURITA PARRALES ALEX SEBASTIAN | I21: M1 | J21: 5 | K21: ¿Recomendaría Óptica Los Andes a un familiar o amigo? | L21: NO | M21: Muy frío la atención | N21: ROBERTO CARLOS VAQUILEMA YAUTIBUG | O21: 0604814921001 | P21: 0959525237 | Q21: si | R21: no
A22: 21 | B22: Enero | C22: 46028 | D22: Telegram | E22: MALL DEL RIO CUENCA | F22: Ventas | G22: AGUILERA CAMACHO JOSE LUIS | H22: NAREA JUELA JUAN ANDRES | I22: M2 | J22: NO | K22: ¿El tiempo de entrega de su producto fue acorde al tiempo ofrecido? | L22: NO | M22: Me dijeron 7-8 días laborables y se demoró 14 días laborables. Aparte tampoco me llegó notificación de que el producto estaba listo por lo que tuve que comunicarme en más de una ocasión por teléfono para constatar el estado del producto | R22: no
A23: 22 | B23: Enero | C23: 46029 | D23: Telegram | E23: MALL DEL NORTE | F23: Ventas | G23: RODRIGUEZ LEON ALEXANDRA GABRIELA | H23: PAREDES LEON CHRISTOPHER HERNAN | I23: M2 | J23: 2 | K23: ¿Recomendaría Óptica Los Andes a un familiar o amigo? | L23: NO | M23: Me entregaron, pero estaba con falla , el producto no lo lo recibo el mismo quedo en la optica para su correccion, aun no lo recibo | N23: PLACIDO VASQUEZ MACIAS | O23: 1708425929 | P23: 0959897107 | Q23: si | R23: no
A24: 23 | B24: Enero | C24: 46029 | D24: Telegram | E24: CONDADO SHOPPING | F24: Ventas | G24: Murillo Dominguez Jhan | H24: HIDALGO MEJIA CRISTIAN DAVID | I24: M2 | J24: 5 | K24: La atención del optómetra con respecto a la explicación del uso del producto fue: | L24: NO | M24: Sin explicación mayor | R24: no
A25: 24 | B25: Enero | C25: 46029 | D25: Telegram | E25: MALL EL JARDIN OSH | F25: Ventas | G25: BAÑO LUCERO DAYANA LISBETH | H25: VERDEZOTO VELEZ JONATHAN ALEXANDER | I25: M1 | J25: 6 | K25: El asesoramiento recibido por el asesor fue: | L25: NO | M25: Fui atendida un largo tiempo después de estar en el establecimiento | R25: no
A26: 25 | B26: Enero | C26: 46029 | D26: Telegram | E26: QUICENTRO SHOPPING | F26: Ventas | G26: NARVAEZ ANDRADE PAUL VINICIO | H26: MINCHALA ANDRADE PABLO PATRICIO | I26: M2 | J26: 2 | K26: La atención del asesor con respecto a la explicación del cuidado y la garantía del producto fue: | L26: NO | M26: En principio, cuando mi esposa fue a retirar los lentes NO hubo ninguna explicacion. Tuvimos que ir nuevamente conmigo y exigir que la optometra le entregue los lentes verificando que todo este correcto. | R26: no
A27: 26 | B27: Enero | C27: 46029 | D27: Telegram | E27: QUICENTRO SHOPPING | F27: Ventas | G27: NARVAEZ ANDRADE PAUL VINICIO | H27: MINCHALA ANDRADE PABLO PATRICIO | I27: M2 | J27: NO | K27: ¿El tiempo de entrega de su producto fue acorde al tiempo ofrecido? | L27: NO | M27: ofrecieron en 5 dias habiles, pero el producto habia estado mucho antes y nunca nos notificaron. Mi esposa tuvo que ir personalmente el dia 6 de enero y le dijeron que los lentes estuivieron desde el 30 de diciembre. NUNCA FUIMOS NOTIFICADOS | R27: no
A28: 27 | B28: Enero | C28: 46029 | D28: Telegram | E28: QUICENTRO SHOPPING | F28: Ventas | G28: NARVAEZ ANDRADE PAUL VINICIO | H28: MINCHALA ANDRADE PABLO PATRICIO | I28: M2 | J28: NO | K28: ¿Le entregaron la factura física el momento de su compra? | L28: NO | M28: la compra fue realizada el 24 de diciembre y me dijeron que me llegaria la factura a mi correo, PERO NUNCA LLEGO. Ayer tuve que pedir que me envien la factura a mi correo. | R28: no
A29: 28 | B29: Enero | C29: 46029 | D29: Telegram | E29: PIAZZA MACHALA | F29: Ventas | G29: HUANCA CASTILLO KERLY ROSA | H29: FERNÁNDEZ GUEVARA JHOMYRA ELIZABETH | I29: M1 | J29: 5 | K29: ¿Qué tan satisfecho está con la explicación que le dio el asesor respecto a la garantía extendida? | L29: NO | M29: Sobre la garantía creo que debería ser más clara la explicación | R29: no
A30: 29 | B30: Enero | C30: 46029 | D30: Telegram | E30: MALL EL JARDIN | F30: Ventas | G30: GUAMAN MARTINEZ MARLLORY ALEXANDRA | H30: FRANKLIN SEBASTIAN VACACELA AGUAYO | I30: M1 | J30: 1 | K30: ¿Recomendaría Óptica Los Andes a un familiar o amigo? | L30: NO | M30: Me ofertan una tecnología de lentes cryzal rock, compro 2 pares unos rayban y otros ton ford, ahora veo que me cambian la tecnología de los ton Ford xq supuestamente los Marcos son más grandes, una falta de seriedad. | N30: FRANCISCO JAVIER ALMENDARIZ VALVERDE | O30: 1720388592 | P30: 0984156370 | Q30: si | R30: no
A31: 30 | B31: Enero | C31: 46030 | D31: Google | E31: QUICENTRO SHOPPING | F31: SAC | G31: NARVAEZ OBANDO LIDIA VERONICA | H31: BETHY LOOR | I31: M1 | J31: 1 | K31: Comentario google | L31: SI | M31: El 30 de noviembre del 2025 compré unos lentes, se me cobró un seguro el cual nunca se explicó que era opcional, ni me hablaron de montos, me comunique con óptica los andes y me indicaron que se me iba a regresar el monto del seguro que NO SOLICITÉ en 15 días, hoy 7 de Enero del 2026 no he tenido respuesta, ni noticias de la devolución de un seguro que no deseaba NO RECOMENDABLE | N31: CARLOS JUMBO | O31: 1722317219 | P31: 0983137071 | R31: si
A32: 31 | B32: Enero | C32: 46030 | D32: Telegram | E32: MULTIPLAZA MIRAFLORES CUENCA | F32: Ventas | G32: PROAÑO ZUÑIGA ANDRES ALEJANDRO | H32: VELIZ MOLINA MAITE NOEMI | I32: M2 | J32: 1 | K32: ¿Recomendaría Óptica Los Andes a un familiar o amigo? | L32: NO | M32: hasta la fecha ni me entregan el producto ni tengo ninguna informacion | N32: JOSE MARIA LANDI CRIOLLO | O32: 0100352012 | P32: 0999999999 | Q32: si | R32: no
A33: 32 | B33: Enero | C33: 46030 | D33: Telegram | E33: MULTIPLAZA MIRAFLORES CUENCA | F33: Ventas | G33: PROAÑO ZUÑIGA ANDRES ALEJANDRO | H33: VELIZ MOLINA MAITE NOEMI | I33: M3 | J33: 2 | K33: La atención del asesor con respecto a la explicación del cuidado y la garantía del producto fue: | L33: NO | M33: no me han comunicado de la garantia | R33: no
A34: 33 | B34: Enero | C34: 46031 | D34: Telegram | E34: POLICENTRO | F34: Ventas | G34: TAPIA PEÑA JESSIE PAMELA | H34: GUERRA PINCAY LIDIA LISBETH | I34: M1 | J34: 6 | K34: El asesoramiento recibido por el asesor fue: | L34: NO | M34: El asesoramiento recibido por el asesor fue: | R34: no
A35: 34 | B35: Enero | C35: 46031 | D35: Telegram | E35: POLICENTRO | F35: Ventas | G35: TAPIA PEÑA JESSIE PAMELA | H35: GUERRA PINCAY LIDIA LISBETH | I35: M1 | J35: 1 | K35: ¿Qué tan satisfecho está con la explicación que le dio el asesor respecto a la garantía extendida? | L35: NO | M35: Nadie me dijo nada de esa garantía solo me la cobraron. | R35: no
A36: 35 | B36: Enero | C36: 46031 | D36: Telegram | E36: MALL EL JARDIN | F36: Ventas | G36: CUASCOTA MALTE ROBERTO CARLOS | H36: FRANKLIN SEBASTIAN VACACELA AGUAYO | I36: M2 | J36: 5 | K36: La atención del asesor con respecto a la explicación del cuidado y la garantía del producto fue: | L36: NO | M36: no me explicaron nada | R36: no
A37: 36 | B37: Enero | C37: 46031 | D37: Telegram | E37: MALL EL JARDIN | F37: Ventas | G37: CUASCOTA MALTE ROBERTO CARLOS | H37: FRANKLIN SEBASTIAN VACACELA AGUAYO | I37: M2 | J37: NO | K37: ¿El tiempo de entrega de su producto fue acorde al tiempo ofrecido? | L37: NO | M37: solicite me envie a otro local cuando al momento de la compra me indicaron que si podian hacerlo pero no fue asi, me toco volver al mismo local a retirar | R37: no
A38: 37 | B38: Enero | C38: 46031 | D38: Telegram | E38: EL DORADO | F38: Ventas | G38: GUERRERO CARBO WILLIE JOEL | H38: PASTUZO ORELLANA MARTHA ALICIA | I38: M2 | J38: 5 | K38: ¿Recomendaría Óptica Los Andes a un familiar o amigo? | L38: NO | M38: Han cambiado la calidad del trabajo. Pese a la toma de medidas, no me siento comoda con los lentes, inclusive pasando el periodo de adaptacion que me pidieron. Esto no me habia pasado con ustedes antes ni con otras opticas. Y lo mismo le paso a mi mamá y hermanas... en total compramos cerca de $3,000 en lentes | N38: MARTHA CECILIA PAZMIÑO ACUÑA | O38: 0914376686 | P38: 0989766923 | Q38: si | R38: no
A39: 38 | B39: Enero | C39: 46031 | D39: Telegram | E39: MALL EL JARDIN | F39: Ventas | G39: GUAMAN MARTINEZ MARLLORY ALEXANDRA | H39: ROBLEZ QUEZADA SANDRA ELIZABET | I39: M2 | J39: NO | K39: ¿El tiempo de entrega de su producto fue acorde al tiempo ofrecido? | L39: NO | M39: No lo fue | R39: no
A40: 39 | B40: Enero | C40: 46032 | D40: Telegram | E40: SAN MARINO | F40: Ventas | G40: ZAMBRANO SANTANA CINDY | H40: RAMIREZ GARCIA JORGE | I40: M3 | J40: 1 | K40: ¿Recomendaría Óptica Los Andes a un familiar o amigo? | L40: NO | M40: Tres meses se demoraron en devolverme mis lentes, tres meses No les interesó como se siente el cliente, no soluciónaron rápido. Cero interés, los de SAC solo llamaban a decir cosas, realizaba preguntas y no sabían contestar, que devolvían la llamada y JAMAS me dieron respuestas concretas. El servicio ha caído horrible de óptica los andes | N40: STEPHANIE DEL ROSARIO DIAZ MORA | O40: 0914188305 | P40: 0999769780 | Q40: si | R40: si | T40: se ha tenido comunicación constante con la cliente, ya se entregaron los lentes, si hubo demora por parte de laboratorio y error en lunas, si fue un caso complicado que nos llevó tiempo resolver
...

Sheet datos por personal
A1: Cargo | B1: Nombre | C1: Enero | D1: Febrero | E1: Marzo | F1: Abril | G1: Mayo | H1: Junio | J1: TOTAL
A2: Optómetra | B2: TAPIA PEÑA JESSIE PAMELA | C2: =+COUNTIFS(GENERAL!$B:$B,'datos por personal'!C$1,GENERAL!$G:$G,'datos por personal'!$B2) -> 7 | D2: =+COUNTIFS(GENERAL!$B:$B,'datos por personal'!D$1,GENERAL!$G:$G,'datos por personal'!$B2) -> 1 | E2: =+COUNTIFS(GENERAL!$B:$B,'datos por personal'!E$1,GENERAL!$G:$G,'datos por personal'!$B2) -> 2 | F2: =+COUNTIFS(GENERAL!$B:$B,'datos por personal'!F$1,GENERAL!$G:$G,'datos por personal'!$B2) -> 1 | G2: =+COUNTIFS(GENERAL!$B:$B,'datos por personal'!G$1,GENERAL!$G:$G,'datos por personal'!$B2) -> 0 | H2: =+COUNTIFS(GENERAL!$B:$B,'datos por personal'!H$1,GENERAL!$G:$G,'datos por personal'!$B2) -> 0 | J2: =+SUM(C2:H2) -> 11 | L2: =358*2 -> 716
A3: Optómetra | B3: ALDANA GOMEZ ANDREA | C3: =+COUNTIFS(GENERAL!$B:$B,'datos por personal'!C$1,GENERAL!$G:$G,'datos por personal'!$B3) -> 1 | D3: =+COUNTIFS(GENERAL!$B:$B,'datos por personal'!D$1,GENERAL!$G:$G,'datos por personal'!$B3) -> 0 | E3: =+COUNTIFS(GENERAL!$B:$B,'datos por personal'!E$1,GENERAL!$G:$G,'datos por personal'!$B3) -> 1 | F3: =+COUNTIFS(GENERAL!$B:$B,'datos por personal'!F$1,GENERAL!$G:$G,'datos por personal'!$B3) -> 1 | G3: =+COUNTIFS(GENERAL!$B:$B,'datos por personal'!G$1,GENERAL!$G:$G,'datos por personal'!$B3) -> 2 | H3: =+COUNTIFS(GENERAL!$B:$B,'datos por personal'!H$1,GENERAL!$G:$G,'datos por personal'!$B3) -> 0 | J3: =+SUM(C3:H3) -> 5 | L3: =+IF(L2=J225,"ok") -> FALSE
A4: Optómetra | B4: BAÑO LUCERO DAYANA LISBETH | C4: =+COUNTIFS(GENERAL!$B:$B,'datos por personal'!C$1,GENERAL!$G:$G,'datos por personal'!$B4) -> 3 | D4: =+COUNTIFS(GENERAL!$B:$B,'datos por personal'!D$1,GENERAL!$G:$G,'datos por personal'!$B4) -> 3 | E4: =+COUNTIFS(GENERAL!$B:$B,'datos por personal'!E$1,GENERAL!$G:$G,'datos por personal'!$B4) -> 0 | F4: =+COUNTIFS(GENERAL!$B:$B,'datos por personal'!F$1,GENERAL!$G:$G,'datos por personal'!$B4) -> 0 | G4: =+COUNTIFS(GENERAL!$B:$B,'datos por personal'!G$1,GENERAL!$G:$G,'datos por personal'!$B4) -> 0 | H4: =+COUNTIFS(GENERAL!$B:$B,'datos por personal'!H$1,GENERAL!$G:$G,'datos por personal'!$B4) -> 1 | J4: =+SUM(C4:H4) -> 7
A5: Optómetra | B5: ECHEVERRIA NOBOA HIPATIA MAGDALENA | C5: =+COUNTIFS(GENERAL!$B:$B,'datos por personal'!C$1,GENERAL!$G:$G,'datos por personal'!$B5) -> 3 | D5: =+COUNTIFS(GENERAL!$B:$B,'datos por personal'!D$1,GENERAL!$G:$G,'datos por personal'!$B5) -> 1 | E5: =+COUNTIFS(GENERAL!$B:$B,'datos por personal'!E$1,GENERAL!$G:$G,'datos por personal'!$B5) -> 4 | F5: =+COUNTIFS(GENERAL!$B:$B,'datos por personal'!F$1,GENERAL!$G:$G,'datos por personal'!$B5) -> 3 | G5: =+COUNTIFS(GENERAL!$B:$B,'datos por personal'!G$1,GENERAL!$G:$G,'datos por personal'!$B5) -> 2 | H5: =+COUNTIFS(GENERAL!$B:$B,'datos por personal'!H$1,GENERAL!$G:$G,'datos por personal'!$B5) -> 0 | J5: =+SUM(C5:H5) -> 13
A6: Optómetra | B6: CASTRO IBARRA CINDY JAZMIN | C6: =+COUNTIFS(GENERAL!$B:$B,'datos por personal'!C$1,GENERAL!$G:$G,'datos por personal'!$B6) -> 4 | D6: =+COUNTIFS(GENERAL!$B:$B,'datos por personal'!D$1,GENERAL!$G:$G,'datos por personal'!$B6) -> 1 | E6: =+COUNTIFS(GENERAL!$B:$B,'datos por personal'!E$1,GENERAL!$G:$G,'datos por personal'!$B6) -> 0 | F6: =+COUNTIFS(GENERAL!$B:$B,'datos por personal'!F$1,GENERAL!$G:$G,'datos por personal'!$B6) -> 0 | G6: =+COUNTIFS(GENERAL!$B:$B,'datos por personal'!G$1,GENERAL!$G:$G,'datos por personal'!$B6) -> 0 | H6: =+COUNTIFS(GENERAL!$B:$B,'datos por personal'!H$1,GENERAL!$G:$G,'datos por personal'!$B6) -> 0 | J6: =+SUM(C6:H6) -> 5
A7: Optómetra | B7: MOJICA GARCIA ALFONSO JAVIER | C7: =+COUNTIFS(GENERAL!$B:$B,'datos por personal'!C$1,GENERAL!$G:$G,'datos por personal'!$B7) -> 1 | D7: =+COUNTIFS(GENERAL!$B:$B,'datos por personal'!D$1,GENERAL!$G:$G,'datos por personal'!$B7) -> 1 | E7: =+COUNTIFS(GENERAL!$B:$B,'datos por personal'!E$1,GENERAL!$G:$G,'datos por personal'!$B7) -> 2 | F7: =+COUNTIFS(GENERAL!$B:$B,'datos por personal'!F$1,GENERAL!$G:$G,'datos por personal'!$B7) -> 0 | G7: =+COUNTIFS(GENERAL!$B:$B,'datos por personal'!G$1,GENERAL!$G:$G,'datos por personal'!$B7) -> 0 | H7: =+COUNTIFS(GENERAL!$B:$B,'datos por personal'!H$1,GENERAL!$G:$G,'datos por personal'!$B7) -> 0 | J7: =+SUM(C7:H7) -> 4
A8: Optómetra | B8: CUASCOTA MALTE ROBERTO CARLOS | C8: =+COUNTIFS(GENERAL!$B:$B,'datos por personal'!C$1,GENERAL!$G:$G,'datos por personal'!$B8) -> 8 | D8: =+COUNTIFS(GENERAL!$B:$B,'datos por personal'!D$1,GENERAL!$G:$G,'datos por personal'!$B8) -> 7 | E8: =+COUNTIFS(GENERAL!$B:$B,'datos por personal'!E$1,GENERAL!$G:$G,'datos por personal'!$B8) -> 1 | F8: =+COUNTIFS(GENERAL!$B:$B,'datos por personal'!F$1,GENERAL!$G:$G,'datos por personal'!$B8) -> 2 | G8: =+COUNTIFS(GENERAL!$B:$B,'datos por personal'!G$1,GENERAL!$G:$G,'datos por personal'!$B8) -> 2 | H8: =+COUNTIFS(GENERAL!$B:$B,'datos por personal'!H$1,GENERAL!$G:$G,'datos por personal'!$B8) -> 2 | J8: =+SUM(C8:H8) -> 22
A9: Optómetra | B9: MORANTE LEON MARIA | C9: =+COUNTIFS(GENERAL!$B:$B,'datos por personal'!C$1,GENERAL!$G:$G,'datos por personal'!$B9) -> 1 | D9: =+COUNTIFS(GENERAL!$B:$B,'datos por personal'!D$1,GENERAL!$G:$G,'datos por personal'!$B9) -> 1 | E9: =+COUNTIFS(GENERAL!$B:$B,'datos por personal'!E$1,GENERAL!$G:$G,'datos por personal'!$B9) -> 0 | F9: =+COUNTIFS(GENERAL!$B:$B,'datos por personal'!F$1,GENERAL!$G:$G,'datos por personal'!$B9) -> 0 | G9: =+COUNTIFS(GENERAL!$B:$B,'datos por personal'!G$1,GENERAL!$G:$G,'datos por personal'!$B9) -> 1 | H9: =+COUNTIFS(GENERAL!$B:$B,'datos por personal'!H$1,GENERAL!$G:$G,'datos por personal'!$B9) -> 0 | J9: =+SUM(C9:H9) -> 3
A10: Optómetra | B10: NUÑEZ MONAR SILVANA GISSELA | C10: =+COUNTIFS(GENERAL!$B:$B,'datos por personal'!C$1,GENERAL!$G:$G,'datos por personal'!$B10) -> 3 | D10: =+COUNTIFS(GENERAL!$B:$B,'datos por personal'!D$1,GENERAL!$G:$G,'datos por personal'!$B10) -> 3 | E10: =+COUNTIFS(GENERAL!$B:$B,'datos por personal'!E$1,GENERAL!$G:$G,'datos por personal'!$B10) -> 2 | F10: =+COUNTIFS(GENERAL!$B:$B,'datos por personal'!F$1,GENERAL!$G:$G,'datos por personal'!$B10) -> 2 | G10: =+COUNTIFS(GENERAL!$B:$B,'datos por personal'!G$1,GENERAL!$G:$G,'datos por personal'!$B10) -> 1 | H10: =+COUNTIFS(GENERAL!$B:$B,'datos por personal'!H$1,GENERAL!$G:$G,'datos por personal'!$B10) -> 4 | J10: =+SUM(C10:H10) -> 15
A11: Optómetra | B11: GUERRERO AIZAGA KATHERINE LIZBETH | C11: =+COUNTIFS(GENERAL!$B:$B,'datos por personal'!C$1,GENERAL!$G:$G,'datos por personal'!$B11) -> 1 | D11: =+COUNTIFS(GENERAL!$B:$B,'datos por personal'!D$1,GENERAL!$G:$G,'datos por personal'!$B11) -> 0 | E11: =+COUNTIFS(GENERAL!$B:$B,'datos por personal'!E$1,GENERAL!$G:$G,'datos por personal'!$B11) -> 0 | F11: =+COUNTIFS(GENERAL!$B:$B,'datos por personal'!F$1,GENERAL!$G:$G,'datos por personal'!$B11) -> 0 | G11: =+COUNTIFS(GENERAL!$B:$B,'datos por personal'!G$1,GENERAL!$G:$G,'datos por personal'!$B11) -> 0 | H11: =+COUNTIFS(GENERAL!$B:$B,'datos por personal'!H$1,GENERAL!$G:$G,'datos por personal'!$B11) -> 1 | J11: =+SUM(C11:H11) -> 2
A12: Optómetra | B12: SAMAN JIMENEZ PAOLO CESAR | C12: =+COUNTIFS(GENERAL!$B:$B,'datos por personal'!C$1,GENERAL!$G:$G,'datos por personal'!$B12) -> 2 | D12: =+COUNTIFS(GENERAL!$B:$B,'datos por personal'!D$1,GENERAL!$G:$G,'datos por personal'!$B12) -> 1 | E12: =+COUNTIFS(GENERAL!$B:$B,'datos por personal'!E$1,GENERAL!$G:$G,'datos por personal'!$B12) -> 0 | F12: =+COUNTIFS(GENERAL!$B:$B,'datos por personal'!F$1,GENERAL!$G:$G,'datos por personal'!$B12) -> 0 | G12: =+COUNTIFS(GENERAL!$B:$B,'datos por personal'!G$1,GENERAL!$G:$G,'datos por personal'!$B12) -> 2 | H12: =+COUNTIFS(GENERAL!$B:$B,'datos por personal'!H$1,GENERAL!$G:$G,'datos por personal'!$B12) -> 1 | J12: =+SUM(C12:H12) -> 6
A13: Optómetra | B13: NARVAEZ OBANDO LIDIA VERONICA | C13: =+COUNTIFS(GENERAL!$B:$B,'datos por personal'!C$1,GENERAL!$G:$G,'datos por personal'!$B13) -> 2 | D13: =+COUNTIFS(GENERAL!$B:$B,'datos por personal'!D$1,GENERAL!$G:$G,'datos por personal'!$B13) -> 2 | E13: =+COUNTIFS(GENERAL!$B:$B,'datos por personal'!E$1,GENERAL!$G:$G,'datos por personal'!$B13) -> 2 | F13: =+COUNTIFS(GENERAL!$B:$B,'datos por personal'!F$1,GENERAL!$G:$G,'datos por personal'!$B13) -> 2 | G13: =+COUNTIFS(GENERAL!$B:$B,'datos por personal'!G$1,GENERAL!$G:$G,'datos por personal'!$B13) -> 2 | H13: =+COUNTIFS(GENERAL!$B:$B,'datos por personal'!H$1,GENERAL!$G:$G,'datos por personal'!$B13) -> 2 | J13: =+SUM(C13:H13) -> 12
A14: Optómetra | B14: POZO RONQUILLO SEBASTIAN GABRIEL | C14: =+COUNTIFS(GENERAL!$B:$B,'datos por personal'!C$1,GENERAL!$G:$G,'datos por personal'!$B14) -> 1 | D14: =+COUNTIFS(GENERAL!$B:$B,'datos por personal'!D$1,GENERAL!$G:$G,'datos por personal'!$B14) -> 0 | E14: =+COUNTIFS(GENERAL!$B:$B,'datos por personal'!E$1,GENERAL!$G:$G,'datos por personal'!$B14) -> 0 | F14: =+COUNTIFS(GENERAL!$B:$B,'datos por personal'!F$1,GENERAL!$G:$G,'datos por personal'!$B14) -> 0 | G14: =+COUNTIFS(GENERAL!$B:$B,'datos por personal'!G$1,GENERAL!$G:$G,'datos por personal'!$B14) -> 0 | H14: =+COUNTIFS(GENERAL!$B:$B,'datos por personal'!H$1,GENERAL!$G:$G,'datos por personal'!$B14) -> 0 | J14: =+SUM(C14:H14) -> 1
A15: Optómetra | B15: AGUILERA CAMACHO JOSE LUIS | C15: =+COUNTIFS(GENERAL!$B:$B,'datos por personal'!C$1,GENERAL!$G:$G,'datos por personal'!$B15) -> 1 | D15: =+COUNTIFS(GENERAL!$B:$B,'datos por personal'!D$1,GENERAL!$G:$G,'datos por personal'!$B15) -> 1 | E15: =+COUNTIFS(GENERAL!$B:$B,'datos por personal'!E$1,GENERAL!$G:$G,'datos por personal'!$B15) -> 2 | F15: =+COUNTIFS(GENERAL!$B:$B,'datos por personal'!F$1,GENERAL!$G:$G,'datos por personal'!$B15) -> 0 | G15: =+COUNTIFS(GENERAL!$B:$B,'datos por personal'!G$1,GENERAL!$G:$G,'datos por personal'!$B15) -> 1 | H15: =+COUNTIFS(GENERAL!$B:$B,'datos por personal'!H$1,GENERAL!$G:$G,'datos por personal'!$B15) -> 0 | J15: =+SUM(C15:H15) -> 5
... A91: Optómetra | B91: ALCHUNDIA CASTRO GABRIELA LEONOR | C91: =+COUNTIFS(GENERAL!$B:$B,'datos por personal'!C$1,GENERAL!$G:$G,'datos por personal'!$B91) -> 0 | D91: =+COUNTIFS(GENERAL!$B:$B,'datos por personal'!D$1,GENERAL!$G:$G,'datos por personal'!$B91) -> 0 | E91: =+COUNTIFS(GENERAL!$B:$B,'datos por personal'!E$1,GENERAL!$G:$G,'datos por personal'!$B91) -> 0 | F91: =+COUNTIFS(GENERAL!$B:$B,'datos por personal'!F$1,GENERAL!$G:$G,'datos por personal'!$B91) -> 0 | G91: =+COUNTIFS(GENERAL!$B:$B,'datos por personal'!G$1,GENERAL!$G:$G,'datos por personal'!$B91) -> 1 | H91: =+COUNTIFS(GENERAL!$B:$B,'datos por personal'!H$1,GENERAL!$G:$G,'datos por personal'!$B91) -> 0 | J91: =+SUM(C91:H91) -> 1
A92: Vendedor | B92: RIVADENEIRA PARRA JONATHAN SEBASTIAN | C92: =+COUNTIFS(GENERAL!$B:$B,'datos por personal'!C$1,GENERAL!$H:$H,'datos por personal'!$B92) -> 4 | D92: =+COUNTIFS(GENERAL!$B:$B,'datos por personal'!D$1,GENERAL!$H:$H,'datos por personal'!$B92) -> 2 | E92: =+COUNTIFS(GENERAL!$B:$B,'datos por personal'!E$1,GENERAL!$H:$H,'datos por personal'!$B92) -> 0 | F92: =+COUNTIFS(GENERAL!$B:$B,'datos por personal'!F$1,GENERAL!$H:$H,'datos por personal'!$B92) -> 1 | G92: =+COUNTIFS(GENERAL!$B:$B,'datos por personal'!G$1,GENERAL!$H:$H,'datos por personal'!$B92) -> 0 | H92: =+COUNTIFS(GENERAL!$B:$B,'datos por personal'!H$1,GENERAL!$H:$H,'datos por personal'!$B92) -> 0 | J92: =+SUM(C92:H92) -> 7
A93: Vendedor | B93: SANCHEZ CHECA BRYAN ADRIAN | C93: =+COUNTIFS(GENERAL!$B:$B,'datos por personal'!C$1,GENERAL!$H:$H,'datos por personal'!$B93) -> 1 | D93: =+COUNTIFS(GENERAL!$B:$B,'datos por personal'!D$1,GENERAL!$H:$H,'datos por personal'!$B93) -> 0 | E93: =+COUNTIFS(GENERAL!$B:$B,'datos por personal'!E$1,GENERAL!$H:$H,'datos por personal'!$B93) -> 1 | F93: =+COUNTIFS(GENERAL!$B:$B,'datos por personal'!F$1,GENERAL!$H:$H,'datos por personal'!$B93) -> 1 | G93: =+COUNTIFS(GENERAL!$B:$B,'datos por personal'!G$1,GENERAL!$H:$H,'datos por personal'!$B93) -> 1 | H93: =+COUNTIFS(GENERAL!$B:$B,'datos por personal'!H$1,GENERAL!$H:$H,'datos por personal'!$B93) -> 0 | J93: =+SUM(C93:H93) -> 4
A94: Vendedor | B94: VERDEZOTO VELEZ JONATHAN ALEXANDER | C94: =+COUNTIFS(GENERAL!$B:$B,'datos por personal'!C$1,GENERAL!$H:$H,'datos por personal'!$B94) -> 3 | D94: =+COUNTIFS(GENERAL!$B:$B,'datos por personal'!D$1,GENERAL!$H:$H,'datos por personal'!$B94) -> 2 | E94: =+COUNTIFS(GENERAL!$B:$B,'datos por personal'!E$1,GENERAL!$H:$H,'datos por personal'!$B94) -> 0 | F94: =+COUNTIFS(GENERAL!$B:$B,'datos por personal'!F$1,GENERAL!$H:$H,'datos por personal'!$B94) -> 0 | G94: =+COUNTIFS(GENERAL!$B:$B,'datos por personal'!G$1,GENERAL!$H:$H,'datos por personal'!$B94) -> 0 | H94: =+COUNTIFS(GENERAL!$B:$B,'datos por personal'!H$1,GENERAL!$H:$H,'datos por personal'!$B94) -> 1 | J94: =+SUM(C94:H94) -> 6
A95: Vendedor | B95: BARRERA GORDON HERMEN GUSTAVO | C95: =+COUNTIFS(GENERAL!$B:$B,'datos por personal'!C$1,GENERAL!$H:$H,'datos por personal'!$B95) -> 1 | D95: =+COUNTIFS(GENERAL!$B:$B,'datos por personal'!D$1,GENERAL!$H:$H,'datos por personal'!$B95) -> 1 | E95: =+COUNTIFS(GENERAL!$B:$B,'datos por personal'!E$1,GENERAL!$H:$H,'datos por personal'!$B95) -> 1 | F95: =+COUNTIFS(GENERAL!$B:$B,'datos por personal'!F$1,GENERAL!$H:$H,'datos por personal'!$B95) -> 2 | G95: =+COUNTIFS(GENERAL!$B:$B,'datos por personal'!G$1,GENERAL!$H:$H,'datos por personal'!$B95) -> 1 | H95: =+COUNTIFS(GENERAL!$B:$B,'datos por personal'!H$1,GENERAL!$H:$H,'datos por personal'!$B95) -> 0 | J95: =+SUM(C95:H95) -> 6
A96: Vendedor | B96: GUERRA PINCAY LIDIA LISBETH | C96: =+COUNTIFS(GENERAL!$B:$B,'datos por personal'!C$1,GENERAL!$H:$H,'datos por personal'!$B96) -> 3 | D96: =+COUNTIFS(GENERAL!$B:$B,'datos por personal'!D$1,GENERAL!$H:$H,'datos por personal'!$B96) -> 0 | E96: =+COUNTIFS(GENERAL!$B:$B,'datos por personal'!E$1,GENERAL!$H:$H,'datos por personal'!$B96) -> 0 | F96: =+COUNTIFS(GENERAL!$B:$B,'datos por personal'!F$1,GENERAL!$H:$H,'datos por personal'!$B96) -> 1 | G96: =+COUNTIFS(GENERAL!$B:$B,'datos por personal'!G$1,GENERAL!$H:$H,'datos por personal'!$B96) -> 0 | H96: =+COUNTIFS(GENERAL!$B:$B,'datos por personal'!H$1,GENERAL!$H:$H,'datos por personal'!$B96) -> 1 | J96: =+SUM(C96:H96) -> 5
A97: Vendedor | B97: ALAVA SOLORZANO JEFFERSON CRISTHIAN | C97: =+COUNTIFS(GENERAL!$B:$B,'datos por personal'!C$1,GENERAL!$H:$H,'datos por personal'!$B97) -> 2 | D97: =+COUNTIFS(GENERAL!$B:$B,'datos por personal'!D$1,GENERAL!$H:$H,'datos por personal'!$B97) -> 0 | E97: =+COUNTIFS(GENERAL!$B:$B,'datos por personal'!E$1,GENERAL!$H:$H,'datos por personal'!$B97) -> 2 | F97: =+COUNTIFS(GENERAL!$B:$B,'datos por personal'!F$1,GENERAL!$H:$H,'datos por personal'!$B97) -> 1 | G97: =+COUNTIFS(GENERAL!$B:$B,'datos por personal'!G$1,GENERAL!$H:$H,'datos por personal'!$B97) -> 0 | H97: =+COUNTIFS(GENERAL!$B:$B,'datos por personal'!H$1,GENERAL!$H:$H,'datos por personal'!$B97) -> 0 | J97: =+SUM(C97:H97) -> 5
A98: Vendedor | B98: DAVILA OSSA MARCELO EDUARDO | C98: =+COUNTIFS(GENERAL!$B:$B,'datos por personal'!C$1,GENERAL!$H:$H,'datos por personal'!$B98) -> 3 | D98: =+COUNTIFS(GENERAL!$B:$B,'datos por personal'!D$1,GENERAL!$H:$H,'datos por personal'!$B98) -> 2 | E98: =+COUNTIFS(GENERAL!$B:$B,'datos por personal'!E$1,GENERAL!$H:$H,'datos por personal'!$B98) -> 1 | F98: =+COUNTIFS(GENERAL!$B:$B,'datos por personal'!F$1,GENERAL!$H:$H,'datos por personal'!$B98) -> 1 | G98: =+COUNTIFS(GENERAL!$B:$B,'datos por personal'!G$1,GENERAL!$H:$H,'datos por personal'!$B98) -> 1 | H98: =+COUNTIFS(GENERAL!$B:$B,'datos por personal'!H$1,GENERAL!$H:$H,'datos por personal'!$B98) -> 0 | J98: =+SUM(C98:H98) -> 8
A99: Vendedor | B99: RUIZ CARREÑO FREDDY SANTIAGO | C99: =+COUNTIFS(GENERAL!$B:$B,'datos por personal'!C$1,GENERAL!$H:$H,'datos por personal'!$B99) -> 3 | D99: =+COUNTIFS(GENERAL!$B:$B,'datos por personal'!D$1,GENERAL!$H:$H,'datos por personal'!$B99) -> 3 | E99: =+COUNTIFS(GENERAL!$B:$B,'datos por personal'!E$1,GENERAL!$H:$H,'datos por personal'!$B99) -> 0 | F99: =+COUNTIFS(GENERAL!$B:$B,'datos por personal'!F$1,GENERAL!$H:$H,'datos por personal'!$B99) -> 0 | G99: =+COUNTIFS(GENERAL!$B:$B,'datos por personal'!G$1,GENERAL!$H:$H,'datos por personal'!$B99) -> 1 | H99: =+COUNTIFS(GENERAL!$B:$B,'datos por personal'!H$1,GENERAL!$H:$H,'datos por personal'!$B99) -> 1 | J99: =+SUM(C99:H99) -> 8
A100: Vendedor | B100: GOMEZ LEON NAYDELYN ESCARLETH | C100: =+COUNTIFS(GENERAL!$B:$B,'datos por personal'!C$1,GENERAL!$H:$H,'datos por personal'!$B100) -> 1 | D100: =+COUNTIFS(GENERAL!$B:$B,'datos por personal'!D$1,GENERAL!$H:$H,'datos por personal'!$B100) -> 0 | E100: =+COUNTIFS(GENERAL!$B:$B,'datos por personal'!E$1,GENERAL!$H:$H,'datos por personal'!$B100) -> 0 | F100: =+COUNTIFS(GENERAL!$B:$B,'datos por personal'!F$1,GENERAL!$H:$H,'datos por personal'!$B100) -> 0 | G100: =+COUNTIFS(GENERAL!$B:$B,'datos por personal'!G$1,GENERAL!$H:$H,'datos por personal'!$B100) -> 1 | H100: =+COUNTIFS(GENERAL!$B:$B,'datos por personal'!H$1,GENERAL!$H:$H,'datos por personal'!$B100) -> 0 | J100: =+SUM(C100:H100) -> 2
A101: Vendedor | B101: YEPEZ PAVON DAVID GUSTAVO | C101: =+COUNTIFS(GENERAL!$B:$B,'datos por personal'!C$1,GENERAL!$H:$H,'datos por personal'!$B101) -> 5 | D101: =+COUNTIFS(GENERAL!$B:$B,'datos por personal'!D$1,GENERAL!$H:$H,'datos por personal'!$B101) -> 2 | E101: =+COUNTIFS(GENERAL!$B:$B,'datos por personal'!E$1,GENERAL!$H:$H,'datos por personal'!$B101) -> 0 | F101: =+COUNTIFS(GENERAL!$B:$B,'datos por personal'!F$1,GENERAL!$H:$H,'datos por personal'!$B101) -> 3 | G101: =+COUNTIFS(GENERAL!$B:$B,'datos por personal'!G$1,GENERAL!$H:$H,'datos por personal'!$B101) -> 1 | H101: =+COUNTIFS(GENERAL!$B:$B,'datos por personal'!H$1,GENERAL!$H:$H,'datos por personal'!$B101) -> 0 | J101: =+SUM(C101:H101) -> 11
A102: Vendedor | B102: GUATEMAL OTAVALO MARIA GABRIELA | C102: =+COUNTIFS(GENERAL!$B:$B,'datos por personal'!C$1,GENERAL!$H:$H,'datos por personal'!$B102) -> 1 | D102: =+COUNTIFS(GENERAL!$B:$B,'datos por personal'!D$1,GENERAL!$H:$H,'datos por personal'!$B102) -> 0 | E102: =+COUNTIFS(GENERAL!$B:$B,'datos por personal'!E$1,GENERAL!$H:$H,'datos por personal'!$B102) -> 0 | F102: =+COUNTIFS(GENERAL!$B:$B,'datos por personal'!F$1,GENERAL!$H:$H,'datos por personal'!$B102) -> 0 | G102: =+COUNTIFS(GENERAL!$B:$B,'datos por personal'!G$1,GENERAL!$H:$H,'datos por personal'!$B102) -> 0 | H102: =+COUNTIFS(GENERAL!$B:$B,'datos por personal'!H$1,GENERAL!$H:$H,'datos por personal'!$B102) -> 1 | J102: =+SUM(C102:H102) -> 2
A103: Vendedor | B103: OCHOA TORRES CESAR ENRIQUE | C103: =+COUNTIFS(GENERAL!$B:$B,'datos por personal'!C$1,GENERAL!$H:$H,'datos por personal'!$B103) -> 2 | D103: =+COUNTIFS(GENERAL!$B:$B,'datos por personal'!D$1,GENERAL!$H:$H,'datos por personal'!$B103) -> 0 | E103: =+COUNTIFS(GENERAL!$B:$B,'datos por personal'!E$1,GENERAL!$H:$H,'datos por personal'!$B103) -> 0 | F103: =+COUNTIFS(GENERAL!$B:$B,'datos por personal'!F$1,GENERAL!$H:$H,'datos por personal'!$B103) -> 0 | G103: =+COUNTIFS(GENERAL!$B:$B,'datos por personal'!G$1,GENERAL!$H:$H,'datos por personal'!$B103) -> 0 | H103: =+COUNTIFS(GENERAL!$B:$B,'datos por personal'!H$1,GENERAL!$H:$H,'datos por personal'!$B103) -> 0 | J103: =+SUM(C103:H103) -> 2
... A222: Vendedor | B222: CHASI ZAMBRANO KARLA LISBETH | C222: =+COUNTIFS(GENERAL!$B:$B,'datos por personal'!C$1,GENERAL!$H:$H,'datos por personal'!$B222) -> 0 | D222: =+COUNTIFS(GENERAL!$B:$B,'datos por personal'!D$1,GENERAL!$H:$H,'datos por personal'!$B222) -> 0 | E222: =+COUNTIFS(GENERAL!$B:$B,'datos por personal'!E$1,GENERAL!$H:$H,'datos por personal'!$B222) -> 0 | F222: =+COUNTIFS(GENERAL!$B:$B,'datos por personal'!F$1,GENERAL!$H:$H,'datos por personal'!$B222) -> 0 | G222: =+COUNTIFS(GENERAL!$B:$B,'datos por personal'!G$1,GENERAL!$H:$H,'datos por personal'!$B222) -> 0 | H222: =+COUNTIFS(GENERAL!$B:$B,'datos por personal'!H$1,GENERAL!$H:$H,'datos por personal'!$B222) -> 1 | J222: =+SUM(C222:H222) -> 1
J225: =+SUM(J2:J222) -> 760

Sheet RESUMEN ENERO-FEBRERO- MARZO
C2: ENERO (1 AL 31) | E2: Observaciones
B3: Ventas | C3: 83 | D3: 0.93 | E3: Garantía / seguro no explicado o cobrado sin informar Demoras en entrega / incumplimiento de plazo
B4: Sac | C4: 1 | D4: 0.01 | E4: Demora en el tiempo de devolución
B5: Optometría | C5: 5 | D5: 0.06 | E5: Medidas incorrectas / errores en graduación Fallas en calidad visual / distorsión
B6: TOTAL | C6: =SUM(C3:C5) -> 89 | D6: =SUM(D3:D5) -> 1
C8: FEBRERO (1 AL 22) | E8: Observaciones
B9: Ventas | C9: 52 | D9: 0.85 | E9: 1. Demoras en entrega / no avisan que el producto está listo 2. Garantía / seguro no explicado o cobrado sin informar 3. Mala atención / falta de asesoría / trato poco profesional
B10: Sac | C10: 0 | D10: 0
B11: Optometría | C11: 9 | D11: 0.15 | E11: 1. Falta de explicación sobre garantía o uso del producto 2. Lentes mal hechos / problemas de calidad visual
B12: TOTAL | C12: =SUM(C9:C11) -> 61 | D12: =SUM(D9:D11) -> 1
C14: FEBRERO (23 AL 29) | E14: Observaciones
B15: Ventas | C15: 14 | D15: 0.9333 | E15: 1. Demoras en entrega / no avisan que el producto está listo 2. Garantía / seguro no explicado o cobrado sin informar 3. Mala atención / falta de asesoría / trato poco profesional
B16: Sac | C16: 0 | D16: 0
B17: Optometría | C17: 1 | D17: 0.0667 | E17: 1. Falta de explicación sobre garantía o uso del producto 2. Lentes mal hechos / problemas de calidad visual
B18: TOTAL | C18: =SUM(C15:C17) -> 15 | D18: =SUM(D15:D17) -> 1
C20: MARZO (01 AL 05) | E20: Observaciones
B21: Ventas | C21: 7 | D21: =C21/7*100 -> 100 | E21: 1. Demoras en entrega / no avisan que el producto está listo 2. Garantía / seguro no explicado o cobrado sin informar 3. Mala atención / falta de asesoría / trato poco profesional
B22: Sac | C22: 0 | D22: 0
B23: Optometría | C23: 0 | D23: 0
B24: TOTAL | C24: =SUM(C21:C23) -> 7 | D24: =SUM(D21:D23) -> 100
C26: MARZO (06 AL 15) | E26: Observaciones
B27: Ventas | C27: 10 | D27: 0.6667 | E27: 1. Demoras en entrega / no avisan que el producto está listo 2. Garantía / seguro no explicado o cobrado sin informar 3. Mala atención / falta de asesoría / trato poco profesional
B28: Sac | C28: 0
B29: Optometría | C29: 5 | D29: 0.3333 | E29: 1. Valor 2. Lentes con medidas incorrectas / incomodidad visual
B30: TOTAL | C30: =SUM(C27:C29) -> 15 | D30: 1
C32: MARZO (16 AL 22) | E32: Observaciones
B33: Ventas | C33: 12 | D33: =C33/C36*100 -> 70.588235 | E33: 1. No avisan que el producto está listo 2. Garantía / seguro no explicado o cobrado sin informar
B34: Sac | C34: 0
B35: Optometría | C35: 5 | D35: =C35/C36*100 -> 29.411765 | E35: 1. Falta de explicación 2. Lentes con medidas incorrectas / incomodidad visual
B36: TOTAL | C36: 17 | D36: 1
C38: MARZO (23 AL 29) | E38: Observaciones
B39: Ventas | C39: 14 | D39: =C39/C42*100 -> 93.333333 | E39: 1. No avisan que el producto está listo 2. demoras en el tiempo ofrecido 3. Garantía / seguro no explicado o cobrado sin informar
B40: Sac | C40: 0
B41: Optometría | C41: 1 | D41: =C41/C42*100 -> 6.6666667 | E41: 1. Falta de explicación
B42: TOTAL | C42: 15 | D42: 1
C44: MARZO (30 AL 31) | E44: Observaciones
B45: Ventas | C45: 1 | D45: =C45/C48*100 -> 100 | E45: 1. No avisan que el producto está listo 2. demoras en el tiempo ofrecido 3. Garantía / seguro no explicado o cobrado sin informar
B46: Sac | C46: 0
B47: Optometría | C47: 0 | D47: =C47/C48*100 -> 0 | E47: 1. Falta de explicación
B48: TOTAL | C48: 1 | D48: 1
...

Sheet Detalle llamadas
D1: no | E1: si
B3: MES | C3: CANTIDAD ALERTAS | D3: No aplica llamada | E3: LLAMADAS | F3: CONTESTÓ | G3: % RESPUESTA | H3: SOLUCIONES
B4: Febrero | C4: =+COUNTIF(GENERAL!$B:$B,'Detalle llamadas'!B4) -> 76 | D4: =+COUNTIFS(GENERAL!$B:$B,'Detalle llamadas'!$B4,GENERAL!$R:$R,$D$1) -> 48 | E4: =+COUNTIFS(GENERAL!$B:$B,'Detalle llamadas'!$B4,GENERAL!$R:$R,$E$1) -> 28 | F4: =+COUNTIFS(GENERAL!$B:$B,'Detalle llamadas'!$B4,GENERAL!$S:$S,"si") -> 18 | G4: =+F4/E4 -> 0.64285714 | H4: =+COUNTIFS(GENERAL!$B:$B,'Detalle llamadas'!$B4,GENERAL!$U:$U,"si") -> 14
B6: MES | C6: CANTIDAD ALERTAS | D6: No aplica llamada | E6: LLAMADAS | F6: CONTESTÓ | G6: % RESPUESTA | H6: SOLUCIONES
B7: Marzo | C7: =+COUNTIF(GENERAL!$B:$B,'Detalle llamadas'!B7) -> 52 | D7: =+COUNTIFS(GENERAL!$B:$B,'Detalle llamadas'!$B7,GENERAL!$R:$R,$D$1) -> 27 | E7: =+COUNTIFS(GENERAL!$B:$B,'Detalle llamadas'!$B7,GENERAL!$R:$R,$E$1) -> 24 | F7: =+COUNTIFS(GENERAL!$B:$B,'Detalle llamadas'!$B7,GENERAL!$S:$S,"si") -> 12 | G7: =+F7/E7 -> 0.5 | H7: =+COUNTIFS(GENERAL!$B:$B,'Detalle llamadas'!$B7,GENERAL!$U:$U,"si") -> 10
B9: MES | C9: CANTIDAD ALERTAS | D9: No aplica llamada | E9: LLAMADAS | F9: CONTESTÓ | G9: % RESPUESTA | H9: SOLUCIONES
B10: Abril | C10: =+COUNTIF(GENERAL!$B:$B,'Detalle llamadas'!B10) -> 58 | D10: =+COUNTIFS(GENERAL!$B:$B,'Detalle llamadas'!$B10,GENERAL!$R:$R,$D$1) -> 4 | E10: =+COUNTIFS(GENERAL!$B:$B,'Detalle llamadas'!$B10,GENERAL!$R:$R,$E$1) -> 51 | F10: =+COUNTIFS(GENERAL!$B:$B,'Detalle llamadas'!$B10,GENERAL!$S:$S,"si") -> 24 | G10: =+F10/E10 -> 0.47058824 | H10: =+COUNTIFS(GENERAL!$B:$B,'Detalle llamadas'!$B10,GENERAL!$U:$U,"si") -> 18

Sheet RESUMEN ABRIL
C1: ABRIL (01 AL 05) | E1: Observaciones
B2: Ventas | C2: 11 | D2: =C2/C5*100 -> 84.615385 | E2: 1. No avisan que el producto está listo 2. demoras en el tiempo ofrecido 3. Garantía / seguro no explicado o cobrado sin informar
B3: Sac | C3: 0
B4: Optometría | C4: 0 | D4: =C4/C5*100 -> 0 | E4: 1. Falta de explicación
B5: TOTAL | C5: 13 | D5: 1
C7: ABRIL (06 AL 12) | E7: Observaciones
B8: Ventas | C8: 13 | D8: =C8/C11*100 -> 72.222222 | E8: 1. No avisan que el producto está listo 2. demoras en el tiempo ofrecido 3. Garantía / seguro no explicado o cobrado sin informar
B9: Sac | C9: 0
B10: Optometría | C10: 5 | D10: =C10/C11*100 -> 27.777778 | E10: 1. demora en la entrega 2. Poco profesionalismo 3. incomodidad visual
B11: TOTAL | C11: 18 | D11: 1
C13: ABRIL (13 AL 16) | E13: Observaciones
B14: Ventas | C14: 7 | D14: =C14/C17*100 -> 87.5 | E14: 1. No avisan que el producto está listo 2. demoras en el tiempo ofrecido 3. Garantía / seguro no explicado o cobrado sin informar
B15: Sac | C15: 0
B16: Optometría | C16: 1 | D16: =C16/C17*100 -> 12.5 | E16: 1. incomodidad visual
B17: TOTAL | C17: 8 | D17: 1
C19: ABRIL (17 AL 23) | E19: Observaciones
B20: Ventas | C20: 11 | D20: =C20/C23*100 -> 137.5 | E20: 1. No avisan que el producto está listo 2. demoras en el tiempo ofrecido 3. Garantía / seguro no explicado o cobrado sin informar
B21: Sac | C21: 0
B22: Optometría | C22: 0 | D22: =C22/C23*100 -> 0
B23: TOTAL | C23: 8 | D23: 1
C25: ABRIL (24 AL 30) | E25: Observaciones
B26: Ventas | C26: 10 | D26: =C26/C29*100 -> 100 | E26: 1. No avisan que el producto está listo 2. demoras en el tiempo ofrecido 3. Garantía / seguro no explicado o cobrado sin informar
B27: Sac | C27: 0
B28: Optometría | C28: 0 | D28: =C28/C29*100 -> 0
B29: TOTAL | C29: 10 | D29: 1
C31: RESUMEN DE ABRIL | E31: Observaciones
B32: Ventas | C32: 52 | D32: =C32/C35*100 -> 89.655172 | E32: 1. No avisan que el producto está listo 2. demoras en el tiempo ofrecido 3. Garantía / seguro no explicado o cobrado sin informar
B33: Sac | C33: 0
B34: Optometría | C34: 6 | D34: =C34/C35*100 -> 10.344828
B35: TOTAL | C35: 58 | D35: 1

Sheet RESUMEN MAYO - JUNIO
C1: MAYO | E1: Observaciones | H1: JUNIO | J1: Observaciones
B2: Ventas | C2: =C8+C14+C20+C26+C32 -> 55 | D2: =C2/C5*100 -> 79.710145 | E2: 1. Demora en la entrega de lentes / incumplimiento de fechas 2. Mala atención al cliente y postventa 3. Falta de información ventas de OLAPLUS | G2: Ventas | H2: =H8+H14+H20+H26+H32 -> 31 | I2: =H2/H5*100 -> 73.809524 | J2: 1. Demora en la entrega de lentes / incumplimiento de fechas 2. Mala atención al cliente y postventa 3. Falta de información ventas de OLAPLUS
B3: Sac | C3: 0 | G3: Sac | H3: 0
B4: Optometría | C4: =C10+C16+C22+C28+C34 -> 14 | D4: =C4/C5*100 -> 20.289855 | E4: 1. Indican queja por mala calidad en materiales 2. incomodidad visual 3. Falta de respuesta o evasión ante reclamos | G4: Optometría | H4: =H10+H16+H22+H28+H34 -> 11 | I4: =H4/H5*100 -> 26.190476 | J4: 1. Indican queja por mala calidad en materiales 2. incomodidad visual 3. Falta de respuesta o evasión ante reclamos
B5: TOTAL | C5: =C2+C3+C4 -> 69 | D5: 1 | G5: TOTAL | H5: =H2+H3+H4 -> 42 | I5: 1
C7: MAYO (1 AL 7) | E7: Observaciones | H7: JUNIO (1 AL 4) | J7: Observaciones
B8: Ventas | C8: 13 | D8: =C8/C11*100 -> 81.25 | E8: 1. No avisan que el producto está listo 2. demoras en el tiempo ofrecido 3. Garantía / seguro no explicado o cobrado sin informar | G8: Ventas | H8: 10 | I8: =H8/H11*100 -> 76.923077 | J8: 1. No avisan que el producto está listo 2. demoras en el tiempo ofrecido 3. Garantía / seguro no explicado o cobrado sin informar
B9: Sac | C9: 0 | G9: Sac | H9: 0
B10: Optometría | C10: 3 | D10: =C10/C11*100 -> 18.75 | E10: Indican queja por mala calidad en materiales incomodidad visual | G10: Optometría | H10: 3 | I10: =H10/H11*100 -> 23.076923 | J10: Indican queja por mala calidad en materiales incomodidad visual
B11: TOTAL | C11: 16 | D11: 1 | G11: TOTAL | H11: =SUM(H8:H10) -> 13
C13: MAYO (8 AL 14) | E13: Observaciones | H13: JUNIO (5 AL 11) | J13: Observaciones
B14: Ventas | C14: 14 | D14: =C14/C17*100 -> 87.5 | E14: 1. Demora en la entrega de lentes / incumplimiento de fechas 2. Mala atención al cliente y postventa 3. Falta de información ventas de OLAPLUS | G14: Ventas | H14: 12 | I14: =H14/H17*100 -> 85.714286 | J14: 1. No avisan que el producto está listo 2. demoras en el tiempo ofrecido 3. Garantía / seguro no explicado o cobrado sin informar
B15: Sac | C15: 0 | G15: Sac | H15: 0
B16: Optometría | C16: 4 | D16: =C16/C17*100 -> 25 | E16: 1. Indican queja por mala calidad en materiales 2. incomodidad visual 3. Falta de respuesta o evasión ante reclamos | G16: Optometría | H16: 2 | I16: =H16/H17*100 -> 14.285714 | J16: incomodidad visual
B17: TOTAL | C17: 16 | D17: 1 | G17: TOTAL | H17: =SUM(H14:H16) -> 14
C19: MAYO (15 AL 21) | E19: Observaciones | H19: JUNIO (12 AL 18) | J19: Observaciones
B20: Ventas | C20: =C8+C116 -> 13 | D20: =C20/C23*100 -> 81.25 | E20: 1. Demora en la entrega de lentes / incumplimiento de fechas 2. Falta de información ventas de OLAPLUS | G20: Ventas | H20: 3 | I20: =H20/H23*100 -> 50 | J20: 1. No avisan que el producto está listo 2. demoras en el tiempo ofrecido 3. Garantía / seguro no explicado o cobrado sin informar
B21: Sac | C21: 0 | G21: Sac | H21: 0
B22: Optometría | C22: 3 | D22: =C22/C23*100 -> 18.75 | E22: 1. Indican queja por mala calidad en materiales 2. incomodidad visual 3. Falta de respuesta o evasión ante reclamos | G22: Optometría | H22: 3 | I22: =H22/H23*100 -> 50 | J22: incomodidad visual
B23: TOTAL | C23: 16 | D23: 1 | G23: TOTAL | H23: =SUM(H20:H22) -> 6
C25: MAYO (22 AL 28) | E25: Observaciones | H25: JUNIO (19 AL 23) | J25: Observaciones
B26: Ventas | C26: 12 | D26: =C26/C29*100 -> 80 | E26: 1. Demora en la entrega de lentes / incumplimiento de fechas 2. Falta de información ventas de OLAPLUS | G26: Ventas | H26: 3 | I26: =H26/H29*100 -> 100 | J26: 1. Repetición de errores en la elaboración de lentes 2. Servicio pésimo 3. Pérdida de tiempo generada por los errores repetidos.
B27: Sac | C27: 0 | G27: Sac | H27: 0
B28: Optometría | C28: 3 | D28: =C28/C29*100 -> 20 | E28: 1. Indican queja por mala calidad en materiales 2. incomodidad visual 3. Falta de respuesta o evasión ante reclamos | G28: Optometría | H28: 0 | I28: =H28/H29*100 -> 0
B29: TOTAL | C29: 15 | D29: 1 | G29: TOTAL | H29: =SUM(H26:H28) -> 3
C31: MAYO (29 AL 31) | E31: Observaciones | H31: JUNIO (24 AL 30) | J31: Observaciones
B32: Ventas | C32: 3 | D32: =C32/C35*100 -> 20 | E32: 1. Mala atención 2. Falta de explicación 3. Falta de comunicación sobre el pedido | G32: Ventas | H32: 3 | I32: =H32/H35*100 -> 50 | J32: 1. Repetición de errores en la elaboración de lentes 2. Servicio pésimo 3. Pérdida de tiempo generada por los errores repetidos.
B33: Sac | C33: 0 | G33: Sac | H33: 0
B34: Optometría | C34: 1 | D34: =C34/C35*100 -> 6.6666667 | E34: 1. incomodidad visual | G34: Optometría | H34: 3 | I34: =H34/H35*100 -> 50 | J34: 1. Inconformidad en el servicio 2. Servicio al cliente desagradable
B35: TOTAL | C35: 15 | D35: 1 | G35: TOTAL | H35: =SUM(H32:H34) -> 6

Sheet OPTOMETRÍA
A1: n | B1: Mes | C1: Fecha | D1: Canal | E1: Local | F1: Área | G1: Optómetra | H1: Asesor | I1: Momento | J1: Calificación | K1: Pregunta | L1: Responde | M1: Comentario | O1: CLIENTE | P1: ID | Q1: CONTACTO
A2: 1 | B2: 3 | C2: Enero | D2: 46024 | E2: Telegram | F2: SAN MARINO | G2: Optometría | H2: TAPIA PEÑA JESSIE PAMELA | I2: RIVADENEIRA PARRA JONATHAN SEBASTIAN | J2: M3 | K2: 1 | L2: ¿Recomendaría Óptica Los Andes a un familiar o amigo? | M2: NO | N2: Me entregaron los lentes con las lunas cambiadas entre sí, y tuve que regresar al día siguiente porque fui donde mi oftalmólogo y me dijo que eran incorrectas las medidas!, cuando regresé a su local del San Marino, la técnica encargada revisó y verificó los lentes y ella se dió cuenta que las lunas estaban cambiadas entre sí!!!...y tuvo el descaro de decirme que ella las había verificado antes de entregarme las!!...o sea que yo las había cambiado!!....cuando no era de ninguna forma eso posible!!!...me enojé mucho por discutirme e insistir en que ella las había entregado perfectas!!... pésima atención!!...a la final las recibí de vuelta pero me quedó la desconfianza por el mal rato que pasé y al haberme dado cuenta que tuvieron falla en su trabajo profesional!!!...no quiero ni usar esos lentes que me costaron más de $400 y a la final me sentí engañada porque la señorita que me atendió en la venta me dijo que era el mejor lente progresivo!!..y resulta que había otro mucho mejor!!... porque los campos visuales laterales me molestan!.... pésima experiencia está vez porque ya les he comprado antes y sin inconvenientes!. | O2: ALEJANDRO SANCHEZ | P2: 0903972685001 | Q2: 0983676992 | S2: Cliente no contestó
A3: 2 | B3: 41 | C3: Enero | D3: 46032 | E3: Telegram | F3: SAN MARINO | G3: Optometría | H3: ZAMBRANO SANTANA CINDY | I3: RAMIREZ GARCIA JORGE | J3: M3 | K3: 1 | L3: ¿Qué tan satisfecho está con la calidad visual y medidas de sus lunas/lentes de contacto? | M3: NO | N3: Luna’s corregidas con fallas como 5 veces, PÉSIMO Pruebas de calidad realizadas contra luz, hasta me enviaron video del famoso trabajo realizado. TERRIBLE
A4: 3 | B4: 71 | C4: Enero | D4: 46044 | E4: Telegram | F4: CONDADO SHOPPING | G4: Optometría | H4: Murillo Dominguez Jhan | I4: QUINTEROS ESPINOZA BERENICE ELISABETH | J4: M2 | K4: 4 | L4: ¿Recomendaría Óptica Los Andes a un familiar o amigo? | M4: NO | N4: La medida de los lentes no es la adecuada | O4: VICTOR EDUARDO BORJA MANTILLA BORJA MANTILLA | P4: 1707024707001 | Q4: 0984373945
A5: 4 | B5: 73 | C5: Enero | D5: 46045 | E5: Telegram | F5: CONDADO SHOPPING | G5: Optometría | H5: Murillo Dominguez Jhan | I5: LOJA ZAMORA MONICA LUCRESIA | J5: M2 | K5: 3 | L5: ¿Recomendaría Óptica Los Andes a un familiar o amigo? | M5: NO | N5: Me entregaron lentes sin medida. Tuve que regresar dos veces al local para que los arreglen. Pésima experiencia | O5: VICTOR HUGO SALAZAR ESCOBAR | P5: 1711049377 | Q5: 0995673189
A6: 5 | B6: 76 | C6: Enero | D6: 46046 | E6: Telegram | F6: RECREO 2 | G6: Optometría | H6: Fuentes Rosero Kevin | I6: CAZAR VILLALBA FERNANDO WLADIMIR | J6: M1 | K6: 6 | L6: ¿Recomendaría Óptica Los Andes a un familiar o amigo? | M6: NO | N6: El servicio de atención por parte del personal muy bueno. Sin embargo el material para la elaboración de las lunas de los lentes se demoraba demasiado en fabricar (3 semanas) | O6: DAVID GODOY | P6: 1721049193 | Q6: 0958761121
A7: 6 | B7: 91 | C7: Febrero | D7: 46054 | E7: Telegram | F7: PASEO SAN FRANCISCO | G7: Optometría | H7: BASANTES POLO LUCIA MONSERRATH | I7: ESPINOSA FERNANDEZ CESAR | J7: M2 | K7: 1 | L7: La atención del optómetra con respecto a la explicación del uso del producto fue: | M7: NO | N7: Me pusieron una medida que no me sirvió. He sido cliente de óptica los Andes desde que empece a usar lente a los 16 años (tengo 42) y nunca me habia pasado esto, fue una primera mala experiencia | O7: MARIA DEL CARMEN BURBANO VALENCIA | P7: 1710682855 | Q7: 0992596377 | R7: si | S7: no contestó
A8: 7 | B8: 93 | C8: Febrero | D8: 46054 | E8: Telegram | F8: MALL EL JARDIN OSH | G8: Optometría | H8: BAÑO LUCERO DAYANA LISBETH | I8: VERDEZOTO VELEZ JONATHAN ALEXANDER | J8: M1 | K8: 4 | L8: Las recomendaciones recibidas por el optómetra fue: | M8: NO | N8: Sus recomendaciones fueron en tono de burla | P8: 1721823514001 | Q8: 0984279842 | S8: mismo cliente
A9: 8 | B9: 108 | C9: Febrero | D9: 46059 | E9: Telegram | F9: SAN LUIS | G9: Optometría | H9: BASANTES POLO LUCIA MONSERRATH | I9: DEL VALLE TRIVIÑO YEXI | J9: M1 | K9: 1 | L9: ¿Qué tan satisfecho está con la explicación que le dio el asesor respecto a la garantía extendida? | M9: NO | N9: No recibí información sobre la garantía extendida, únicamente el PDF que me llegó adjunto a la factura. De hecho, me di cuenta que me facturaron el seguro al revisar la factura. No recibí información. | O9: ISABEL IDROBO MIÑO | P9: 0503333023 | Q9: 0999951121
A10: 9 | B10: 112 | C10: Febrero | D10: 46062 | E10: Telegram | F10: RIOCENTRO ENTRE RIOS | G10: Optometría | H10: REINA MINDA RAUL RENE | I10: RAMIREZ GARCIA JORGE | J10: M2 | K10: 5 | L10: ¿Recomendaría Óptica Los Andes a un familiar o amigo? | M10: NO | N10: Lo lenes proresivos que me entregaron funcionan muy mal. La optica los tiene para revisar… habra que ver que me dien. Aun no tengo respuesta. | O10: FRANCISCO PONS ZEVALLOS | P10: 0908579071 | Q10: 0999489366
A11: 10 | B11: 118 | C11: Febrero | D11: 46063 | E11: Telegram | F11: MALL DEL PACIFICO MANTA | G11: Optometría | H11: GARCIA OSTAIZA GEMA | I11: PALMA QUIMIS NOEMI ROSALIA | J11: M3 | K11: 1 | L11: ¿Recomendaría Óptica Los Andes a un familiar o amigo? | M11: NO | N11: Validarlo como 0. Productos que no sirven. Se rayan de la nada. | O11: JOHN PAUL BOCANEDES TUMBACO | P11: 1311510497 | Q11: 0963807773
A12: 11 | B12: 120 | C12: Febrero | D12: 46063 | E12: Telegram | F12: SCALA SHOPPING | G12: Optometría | H12: BARAHONA CAÑAS ANDRES WLADIMIR | I12: ALMACHE JARAMILLO STALIN ALEXIS | J12: M3 | K12: 1 | L12: ¿Qué tan satisfecho está con los beneficios de su armazón/gafas/lunas/lentes de contacto? | M12: NO | N12: Los lentes mal hechos, en tres ocasiones no me han cumplido con las medidas correctas | O12: FRANCISCO MIGUEL PONCE PALACIOS | P12: 1702369214 | Q12: 0993372372
A13: 12 | B13: 122 | C13: Febrero | D13: 46064 | E13: Telegram | F13: SAN LUIS | G13: Optometría | H13: BASANTES POLO LUCIA MONSERRATH | I13: DAVILA OSSA MARCELO EDUARDO | J13: M2 | K13: 1 | L13: ¿Recomendaría Óptica Los Andes a un familiar o amigo? | M13: NO | N13: Pésimo producto | O13: CARLA BECERRA PINGUIL | P13: 1726063694 | Q13: 0963963315 | R13: si | S13: queja por mala asesoría/ se devuelve OLA PLUS
A14: 13 | B14: 125 | C14: Febrero | D14: 46066 | E14: Telegram | F14: RIOCENTRO LOS CEIBOS 2 | G14: Optometría | H14: JARAMILLO VERA MARIA CAROLINA | I14: SANCHEZ SIFUENTES MIRIAN | J14: M2 | K14: 2 | L14: ¿Recomendaría Óptica Los Andes a un familiar o amigo? | M14: NO | N14: Estaba mal hecha la medida, he tenido que ir 4 veces para que me reciban los lentes y ingresen el reclamo de incomodidad visual. Llevo una semana esperando que me llamen o me escriban con alguna actualización del reclamo. Sigo esperando mis lentes. | O14: BERNARDO MEITZNER | P14: 918743477 | Q14: 0999382695 | R14: si | S14: ya fue al local, mejoró la atención está a la espera de los nuevos lentes (no fue el mismo asesor de la venta)
A15: 14 | B15: 136 | C15: Febrero | D15: 46071 | E15: Telegram | F15: QUICENTRO SHOPPING | G15: Optometría | H15: NUÑEZ MONAR SILVANA GISSELA | I15: LAGLA CARRION ALEX | J15: M2 | K15: 1 | L15: ¿Recomendaría Óptica Los Andes a un familiar o amigo? | M15: NO | N15: Siento que no es medida de lente, | O15: MARIANA CARLA PIZARRO ORTIZ | P15: 1713862058 | Q15: 0995974211 | R15: si | S15: no contestó
